Workbook

Sheet Legende
A1: Anfertiger: Valentin Maresch, Bernhard Raab, Hannes Hertel(Marketing)
A3: Diese Excel ist auf Deutsch, abgesprochen mit Professor Wach am 04.12.2025
A5: Folien:
A6: Allgemein: Überblick über die geläufigsten Elektro und Hybrid Autos
A7: Strompreis: Kosten für das Verwenden von Strom im Durchschnitt
A8: Nachfrage Jahr 1 - Jahr 3: Berechnung wie hoch das mögliche Nachfragepotential ausfallen könnte
A9: Schätzung Wallboxbesitzer: Folie auf die die Folie der Angebotsentwicklung basiert
A10: Angebotsentwicklung: Skizzierung und Annahmen bezüglich der Entwicklung unserer Wallboxeigentümer für die wir Kunden vermitteln
A11: Umsatz Detail: Kalkulation der Kosten die für den Stellplatzmieter anfallen für das Aufladen an einer Ladestation die von Smart Shift vermittelt wurde
A12: GuV Tabelle: Prognostiziertedarstellung von Umsatz, Kosten und Gewinn für
A13: Break Even Analysis: Grafiken die den Verlauf des Umsatzes
A14: Marketing Analyse

Sheet Allgemein
A1: Anfertiger: | B1: Valentin Maresch | C1: Bernhard Raab
A3: Elektroautos | H3: Kosten pro Ladung | Q3: Wallboxen im Überblick
A4: Rang | B4: Modell | C4: Batteriekapazität (netto, kWh) | D4: Max. DC-Ladeleistung (kW) | E4: AC-Ladeleistung (kW) | H4: Aufladung Privat | J4: Ladezeit in h | Q4: Kategorie | R4: Leistung kWh /h | S4: Komplett Ladezeit h | T4: 20-80%
A5: 1 | B5: Volkswagen ID.7 | C5: 86 | D5: 175 | E5: 11 | H5: 0-100% | I5: =C26*Strompreis!E12 -> 21.883804 | J5: =C26/R7 -> 6.6931818
A6: 2 | B6: Volkswagen ID.3 | C6: 77 | D6: 170 | E6: 11 | H6: 20-80% | I6: =(C26*0.6)*Strompreis!E12 -> 13.130283 | J6: =(C26*0.6)/R7 -> 4.0159091 | Q6: Langsam (AC) | R6: 3.7 | S6: =$C$26/R6 -> 19.898649 | T6: =($C$26*0.6)/R6 -> 11.939189
A7: 3 | B7: Volkswagen ID.4 (inkl. ID.5) | C7: 77 | D7: 135 | E7: 11 | Q7: Standard (AC) | R7: 11 | S7: =$C$26/R7 -> 6.6931818 | T7: =($C$26*0.6)/R7 -> 4.0159091
A8: 4 | B8: Škoda Enyaq | C8: 77 | D8: 135 | E8: 11 | H8: Aufladung Autobahn | Q8: High Power (AC) | R8: 22 | S8: =$C$26/R8 -> 3.3465909 | T8: =($C$26*0.6)/R8 -> 2.0079545
A9: 5 | B9: Škoda Elroq | C9: 77 | D9: 150 | E9: 11 | H9: 0-100% | I9: =C26*Strompreis!E23 -> 49.32875 | Q9: Schnellader (DC) | R9: 50 | S9: =$C$26/R9 -> 1.4725 | T9: =($C$26*0.6)/R9 -> 0.8835
A10: 6 | B10: Cupra Born | C10: 58 | D10: 120 | E10: 11 | H10: 20-80% | I10: =(C26*0.6)*Strompreis!E23 -> 29.59725
A11: 7 | B11: BMW iX1 | C11: 64.7 | D11: 130 | E11: 11
A12: 8 | B12: Mini Electric | C12: 54.2 | D12: 75 | E12: 11
A13: 9 | B13: Cupra Tavascan | C13: 82 | D13: 135 | E13: 11
A14: 10 | B14: Tesla Model Y | C14: 75 | D14: 210 | E14: 11
A15: 11 | B15: Audi Q8 e-tron | C15: 106 | D15: 170 | E15: 11
A16: 12 | B16: Audi Q4 e-tron | C16: 77 | D16: 135 | E16: 11
A17: 13 | B17: Audi A6 e-tron | C17: 100 | D17: 270 | E17: 11
A18: 14 | B18: BMW i4 | C18: 83.9 | D18: 205 | E18: 11
A19: 15 | B19: Hyundai Inster | C19: 49 | D19: 80 | E19: 11
A20: 16 | B20: Ford Explorer | C20: 77 | D20: 185 | E20: 11
A21: 17 | B21: Mercedes-Benz EQA | C21: 70.5 | D21: 100 | E21: 11
A22: 18 | B22: BMW i5 | C22: 81.2 | D22: 205 | E22: 11
... A24: 20 | B24: Fiat 500 Elektro | C24: 42 | D24: 85 | E24: 11
B26: Mittelwert: | C26: =AVERAGE(C5:C24) -> 73.625 | D26: =AVERAGE(D5:D24) -> 148.6 | E26: =AVERAGE(E5:E24) -> 11
A35: Plug-In Autos | H35: Kosten pro Ladung
A36: Rang | B36: Modell | C36: Batteriekapazität (netto, kWh) | D36: Max. DC-Ladeleistung (kW) | E36: AC-Ladeleistung (kW) | H36: Aufladung Privat | J36: Ladezeit in h
A37: 1 | B37: BMW 330e | C37: 12 | E37: 3.7 | H37: 0-100% | I37: =C58*Strompreis!E12 -> 4.8984053 | J37: =C58/E58 -> 3.2124756
A38: 2 | B38: BMW 530e | C38: 12 | E38: 3.7 | H38: 20-80% | I38: =(C58*0.6)*Strompreis!E12 -> 2.9390432 | J38: =(C58*0.6)/E58 -> 1.9274854
A39: 3 | B39: BMW X5 50e | C39: 25.7 | E39: 7.4
A40: 4 | B40: Mercedes C300e | C40: 25.4 | D40: 55 | E40: 11 | H40: Aufladung Autobahn
A41: 5 | B41: Mercedes E300e | C41: 25.4 | D41: 55 | E41: 11 | H41: 0-100% | I41: =C58*Strompreis!E23 -> 11.0416
A42: 6 | B42: Mercedes GLC300e | C42: 31.2 | D42: 60 | E42: 11 | H42: 20-80% | I42: =(C58*0.6)*Strompreis!E23 -> 6.62496
A43: 7 | B43: Volvo XC60 T8 | C43: 18.8 | E43: 3.7
A44: 8 | B44: Volvo XC90 T8 | C44: 18.8 | E44: 3.7
A45: 9 | B45: VW Passat GTE | C45: 13 | E45: 3.6
A46: 10 | B46: VW Tiguan eHybrid | C46: 13 | E46: 3.6
A47: 11 | B47: Audi Q5 55 TFSI e | C47: 17.9 | E47: 7.4
A48: 12 | B48: Audi A3 e‑tron | C48: 8.8 | E48: 3.7
A49: 13 | B49: Skoda Superb iV | C49: 13 | E49: 3.6
A50: 14 | B50: Skoda Octavia iV | C50: 13 | E50: 3.6
A51: 15 | B51: Seat Leon eHybrid | C51: 13 | E51: 3.6
...

Sheet Strompreis
A1: Anfertiger: | B1: Valentin Maresch | C1: Bernhard Raab
B3: Stromtarife und Kosten
B4: Anbieter | C4: Tarif | D4: ct/kWh | E4: €/kWh
B5: Stadtwerke München | C5: Grundversorgung M-Strom | D5: 37.57 | E5: =D5/100 -> 0.3757
B6: Vattenfall | C6: ÖkoStrom12 | D6: 31 | E6: =D6/100 -> 0.31
B7: LEW | C7: Strom Fix Natur | D7: 33.56 | E7: =D7/100 -> 0.3356
B8: Montana | C8: ÖkoStrom Basic (12M) | D8: 24.48 | E8: =D8/100 -> 0.2448
B9: E.ON | C9: ÖkoStrom Extra 12 | D9: 29.99 | E9: =D9/100 -> 0.2999
B10: Rabot Charge | C10: rabot.home flex | D10: 21.74 | E10: =D10/100 -> 0.2174
C12: Mittelwert | D12: =AVERAGE(D5:D10) -> 29.723333 | E12: =D12/100 -> 0.29723333
B16: Autobahn Tarife und Kosten
B17: Anbieter | E17: €/kWh
B18: Ionity | E18: 0.75
B19: EnBW mobility + | E19: 0.87
B20: EWE Go | E20: 0.52
B21: Öffentliche AC Säulen | E21: 0.55
B22: Öffentliche DC Säulen | E22: 0.66
E23: =AVERAGE(E18:E22) -> 0.67

Sheet Schätzung Wallboxbesitzer
A1: Anfertiger: | B1: Valentin Maresch | C1: Bernhard Raab
A3: Prognose der Wallboxeigentümer mit eigener Wallbox bis 2030
B4: E-Autos | C4: Plug-In Hybrid
A5: Prozentualer Anteil Wallboxeigentümer 2025 | B5: 0.7 | C5: 0.2
A6: Prozentualer Anteil ohne Wallbox | B6: 0.3 | C6: 0.8
A7: Anzahl E-Autos in den Fokusgebieten | B7: ='Nachfrage Jahr 3'!E8 -> 7900.5696 | C7: ='Nachfrage Jahr 3'!H8 -> 6284.544
A8: Anzahl E-Auto Besitzer mit Wallbox in den Fokusgebieten | B8: =B7*B5 -> 5530.3987 | C8: =C7*C5 -> 1256.9088
A9: Anzahl E-Auto Besitzer ohne Wallbox | B9: =B7-B8 -> 2370.1709 | C9: =C7-C8 -> 5027.6352
I27: 2023 | J27: 0.8 | L27: Rückgang pro Jahr: | M27: =(J27-J34)/7 -> 0.047142857
I28: 2024 | J28: =J27-$M$27 -> 0.75285714
I29: 2025 | J29: =J28-$M$27 -> 0.70571429
I30: 2026 | J30: =J29-$M$27 -> 0.65857143
I31: 2027 | J31: =J30-$M$27 -> 0.61142857
I32: 2028 | J32: =J31-$M$27 -> 0.56428571
I33: 2029 | J33: =J32-$M$27 -> 0.51714286
I34: 2030 | J34: 0.47

Sheet Nachfrage Jahr 1
A1: Anfertiger: | B1: Valentin Maresch | C1: Bernhard Raab
B3: Geschätzte Nachfrage Jahr 1
B4: Bogenhausen, Trudering-Riem, Berg am Laim, Ramersdorf-Perlach
E5: E-Auto Anzahl | H5: Plug In
A7: Hauptzielgruppe: Anwohner in den Fokusregionen | B7: Anzahl PKWS Gesamt München | C7: 752873
B8: Anzahl PKW in Fokusregionen | C8: =43783+38054+19500+48295 -> 149632 | E8: =C8*E9 -> 7900.5696 | H8: =C8*4.2% -> 6284.544
B9: Proz. Anteil E-Auto&Hybridauto München | E9: 0.0528 | H9: =31000/C7 -> 0.041175603
B10: Anzahl PKW ohne Wallbox (Schätzung) | E10: ='Schätzung Wallboxbesitzer'!B9 -> 2370.1709 | H10: =H8*'Schätzung Wallboxbesitzer'!C6 -> 5027.6352
B11: gesch. Anteil lädt bei uns tgl. | C11: 0.005 | E11: =E10*C11 -> 11.850854 | H11: =(C11*H10)*I11 -> 2.5138176 | I11: 0.1
A13: Nebenzielgruppe 1: Messebesucher | B13: Messebesucher 2025 | C13: 2500000
B14: Proz. Anteil Anreise mit Auto (Schätzung) | C14: 0.4
B15: Anzahl Messebesucher Autos gesamt (Schätzung) | C15: =C13*C14 -> 1000000
B16: Proz. Anteil Messebesucher Autos in Europa | E16: 0.023 | H16: 0.025
B17: Anzahl Messebesucher relevante Autos gesamt | E17: =C15*E16 -> 23000 | H17: =C15*H16 -> 25000
B18: gesch. Anteil lädt bei uns p.a. | C18: 0.001 | E18: =E17*C18 -> 23 | H18: =(H17*C18)*I18 -> 2.5 | I18: 0.1
A20: Nebenzielgruppe 2: Pendler | B20: Pendler tgl. in München | C20: 529834 | M20: -
B21: Pendler tgl. in München mit dem Auto | C21: =C20*C22 -> 291408.7 | E21: =C21*E9 -> 15386.379 | H21: =C21*H9 -> 11998.929
B22: Proz. Anteil Auto Pendler München | C22: 0.55
B23: Anzahl Messebesucher relevante Autos gesamt | C23: =C21*C22 -> 160274.79
B24: Pendler tgl. in Fokusgebieten mit dem Auto | C24: =C23*4/24 -> 26712.464 | E24: =C24*E9 -> 1410.4181 | H24: =(C24*H9)*I24 -> 109.99018 | I24: 0.1
B25: gesch. Anteil lädt bei uns p.a. | C25: 0.0001 | E25: =C25*E24*360 -> 50.775052 | H25: =C25*H24*360 -> 3.9596466
B30: Potentielle monatliche Nachfrage | E30: =(E11*10)+(E18/12)+(E25/12) -> 124.65646 | H30: =(H11*10)+(H18/12)+(H25/12) -> 25.67648 | J30: =E30+H30 -> 150.33294
B32: Potentielle jährliche Nachfrage | J32: =J30*12 -> 1803.9953

Sheet Nachfrage Jahr 2
A1: Anfertiger: | B1: Valentin Maresch | C1: Bernhard Raab
B3: Geschätzte Nachfrage Jahr 2
B4: Bogenhausen, Trudering-Riem, Berg am Laim, Ramersdorf-Perlach
E5: E-Auto Anzahl | H5: Plug In
A7: Hauptzielgruppe: Anwohner in den Fokusregionen | B7: Anzahl PKWS Gesamt München | C7: 752873
B8: Anzahl PKW in Fokusregionen | C8: =43783+38054+19500+48295 -> 149632 | E8: =C8*E9 -> 7900.5696 | H8: =C8*4.2% -> 6284.544
B9: Proz. Anteil E-Auto&Hybridauto München | E9: 0.0528 | H9: =31000/C7 -> 0.041175603
B10: Anzahl PKW ohne Wallbox (Schätzung) | E10: ='Schätzung Wallboxbesitzer'!B9 -> 2370.1709 | H10: =H8*'Schätzung Wallboxbesitzer'!C6 -> 5027.6352
B11: gesch. Anteil lädt bei uns tgl. | C11: 0.01 | E11: =E10*C11 -> 23.701709 | H11: =(C11*H10)*I11 -> 5.0276352 | I11: 0.1
A13: Nebenzielgruppe 1: Messebesucher | B13: Messebesucher 2025 | C13: 2500000
B14: Proz. Anteil Anreise mit Auto (Schätzung) | C14: 0.4
B15: Anzahl Messebesucher Autos gesamt (Schätzung) | C15: =C13*C14 -> 1000000
B16: Proz. Anteil Messebesucher Autos in Europa | E16: 0.023 | H16: 0.025
B17: Anzahl Messebesucher relevante Autos gesamt | E17: =C15*E16 -> 23000 | H17: =C15*H16 -> 25000
B18: gesch. Anteil lädt bei uns p.a. | C18: 0.003 | E18: =E17*C18 -> 69 | H18: =(H17*C18)*I18 -> 7.5 | I18: 0.1
A20: Nebenzielgruppe 2: Pendler | B20: Pendler tgl. in München | C20: 529834
B21: Pendler tgl. in München mit dem Auto | C21: =C20*C22 -> 291408.7 | E21: =C21*E9 -> 15386.379 | H21: =C21*H9 -> 11998.929
B22: Proz. Anteil Auto Pendler München | C22: 0.55
B23: Anzahl Messebesucher relevante Autos gesamt | C23: =C21*C22 -> 160274.79
B24: Pendler tgl. in Fokusgebieten mit dem Auto | C24: =C23*4/24 -> 26712.464 | E24: =C24*E9 -> 1410.4181 | H24: =(C24*H9)*I24 -> 109.99018 | I24: 0.1
B25: gesch. Anteil lädt bei uns p.a. | C25: 0.0003 | E25: =C25*E24*360 -> 152.32516 | H25: =C25*H24*360 -> 11.87894
B30: Potentielle monatliche Nachfrage | E30: =(E11*10)+(E18/12)+(E25/12) -> 255.46085 | H30: =(H11*10)+(H18/12)+(H25/12) -> 51.891264 | J30: =E30+H30 -> 307.35211
B32: Potentielle jährliche Nachfrage | J32: =J30*12 -> 3688.2254

Sheet Nachfrage Jahr 3
A1: Anfertiger: | B1: Valentin Maresch | C1: Bernhard Raab
B3: Geschätzte Nachfrage Jahr 3
B4: Bogenhausen, Trudering-Riem, Berg am Laim, Ramersdorf-Perlach
E5: E-Auto Anzahl | H5: Plug In
A7: Hauptzielgruppe: Anwohner in den Fokusregionen | B7: Anzahl PKWS Gesamt München | C7: 752873
B8: Anzahl PKW in Fokusregionen | C8: =43783+38054+19500+48295 -> 149632 | E8: =C8*E9 -> 7900.5696 | H8: =C8*4.2% -> 6284.544
B9: Proz. Anteil E-Auto&Hybridauto München | E9: 0.0528 | H9: =31000/C7 -> 0.041175603
B10: Anzahl PKW ohne Wallbox (Schätzung) | E10: ='Schätzung Wallboxbesitzer'!B9 -> 2370.1709 | H10: =H8*'Schätzung Wallboxbesitzer'!C6 -> 5027.6352
B11: gesch. Anteil lädt bei uns tgl. | C11: 0.015 | E11: =E10*C11 -> 35.552563 | H11: =(C11*H10)*I11 -> 7.5414528 | I11: 0.1
A13: Nebenzielgruppe 1: Messebesucher | B13: Messebesucher 2025 | C13: 2500000
B14: Proz. Anteil Anreise mit Auto (Schätzung) | C14: 0.4
B15: Anzahl Messebesucher Autos gesamt (Schätzung) | C15: =C13*C14 -> 1000000
B16: Proz. Anteil Messebesucher Autos in Europa | E16: 0.023 | H16: 0.025
B17: Anzahl Messebesucher relevante Autos gesamt | E17: =C15*E16 -> 23000 | H17: =C15*H16 -> 25000
B18: gesch. Anteil lädt bei uns p.a. | C18: 0.005 | E18: =E17*C18 -> 115 | H18: =(C18*H17)*I18 -> 12.5 | I18: 0.1
A20: Nebenzielgruppe 2: Pendler | B20: Pendler tgl. in München | C20: 529834
B21: Pendler tgl. in München mit dem Auto | C21: =C20*C22 -> 291408.7 | E21: =C21*E9 -> 15386.379 | H21: =C21*H9 -> 11998.929
B22: Proz. Anteil Auto Pendler München | C22: 0.55
B23: Anzahl Messebesucher relevante Autos gesamt | C23: =C21*C22 -> 160274.79
B24: Pendler tgl. in Fokusgebieten mit dem Auto | C24: =C23*(4/24) -> 26712.464 | E24: =C24*E9 -> 1410.4181 | H24: =(C24*H9)*I24 -> 109.99018 | I24: 0.1
B25: gesch. Anteil lädt bei uns p.a. | C25: 0.0005 | E25: =C25*E24*360 -> 253.87526 | H25: =C25*H24*360 -> 19.798233
B30: Potentielle monatliche Nachfrage | E30: =(E11*15)+(E18/12)+(E25/12) -> 564.02805 | H30: =(H11*15)+(H18/12)+(H25/12) -> 115.81331 | J30: =E30+H30 -> 679.84136
B32: Potentielle jährliche Nachfrage | J32: =J30*12 -> 8158.0964

Sheet Angebotsentwicklung
A1: Anfertiger: | B1: Valentin Maresch | C1: Bernhard Raab
B3: Anzahl Hosts in Fokus (Bogenhausen, Trudering-Riem, Berg am Laim, Ramersdorf-Perlach)
C5: E-Autos | D5: Plug-In | E5: Gesamt
B7: Anzahl Fokusautos | C7: ='Nachfrage Jahr 3'!E8 -> 7900.5696 | D7: ='Nachfrage Jahr 3'!H8 -> 6284.544 | E7: =SUM(C7:D7) -> 14185.114
B8: Anteil E-Auto Besitzer mit Wallbox | C8: ='Schätzung Wallboxbesitzer'!B5 -> 0.7 | D8: ='Schätzung Wallboxbesitzer'!C5 -> 0.2
B9: Anzahl E-Auto Besitzer mit Wallbox | C9: =C7*C8 -> 5530.3987 | D9: =D7*D8 -> 1256.9088 | E9: =SUM(C9:D9) -> 6787.3075
B13: Anzahl Ladungen bei Hosts in Fokusregionen die mit uns zusammenarbeiten | I13: Anzahl Ladungen pro Monat Ladekapazität Anbieter | U13: Anzahl Ladungen pro Jahr | V13: Mntl. Zuwachs
I14: Jan | J14: Feb | K14: Mrz | L14: Apr | M14: Mai | N14: Jun | O14: Jul | P14: Aug | Q14: Sep | R14: Okt | S14: Nov | T14: Dez | U14: Summe
C15: Jahr 1 | D15: Jahr 2 | E15: Jahr 3 | H15: 1. Jahr | I15: 10 | J15: =I15+$V$15 -> 20.522377 | K15: =J15+$V$15 -> 31.044755 | L15: =K15+$V$15 -> 41.567132 | M15: =L15+$V$15 -> 52.089509 | N15: =M15+$V$15 -> 62.611887 | O15: =N15+$V$15 -> 73.134264 | P15: =O15+$V$15 -> 83.656641 | Q15: =P15+$V$15 -> 94.179018 | ... T15: =S15+$V$15 -> 125.74615 | U15: =C21 -> 814.4769 | V15: =(U15-12*I15)/66 -> 10.522377
B16: Prozentualer Anteil | C16: 0.001 | D16: 0.003 | E16: 0.005 | H16: 2. Jahr | I16: =T15+V15 -> 136.26853 | J16: =I16+$V$16 -> 148.51411 | K16: =J16+$V$16 -> 160.75969 | L16: =K16+$V$16 -> 173.00527 | M16: =L16+$V$16 -> 185.25085 | N16: =M16+$V$16 -> 197.49643 | O16: =N16+$V$16 -> 209.74202 | P16: =O16+$V$16 -> 221.9876 | Q16: =P16+$V$16 -> 234.23318 | ... T16: =S16+$V$16 -> 270.96992 | U16: =D21 -> 2443.4307 | V16: =(U16-12*I16)/66 -> 12.245581
B17: Anzahl durchschnittliche Ladungen pro Tag | C17: =$E$9*C16 -> 6.7873075 | D17: =$E$9*D16 -> 20.361923 | E17: =$E$9*E16 -> 33.936538 | H17: 3. Jahr | I17: =T16+V16 -> 283.2155 | J17: =I17+$V$17 -> 293.42457 | K17: =J17+$V$17 -> 303.63364 | L17: =K17+$V$17 -> 313.84271 | M17: =L17+$V$17 -> 324.05177 | N17: =M17+$V$17 -> 334.26084 | O17: =N17+$V$17 -> 344.46991 | P17: =O17+$V$17 -> 354.67898 | Q17: =P17+$V$17 -> 364.88804 | ... T17: =S17+$V$17 -> 395.51525 | U17: =E21 -> 4072.3845 | V17: =(U17-12*I17)/66 -> 10.209067
B19: Monatlicher Durchschnitt | C19: =C17*10 -> 67.873075 | D19: =D17*10 -> 203.61923 | E19: =E17*10 -> 339.36538
B21: Jahr | C21: =C19*12 -> 814.4769 | D21: =D19*12 -> 2443.4307 | E21: =E19*12 -> 4072.3845 | I21: Anzahl Wallbox Eigentümer die über unsere Plattform vermieten
I22: Jan | J22: Feb | K22: Mrz | L22: Apr | M22: Mai | N22: Jun | O22: Jul | P22: Aug | Q22: Sep | R22: Okt | S22: Nov | T22: Dez
H23: 1. Jahr | I23: =I15/10 -> 1 | J23: =J15/10 -> 2.0522377 | K23: =K15/10 -> 3.1044755 | L23: =L15/10 -> 4.1567132 | M23: =M15/10 -> 5.2089509 | N23: =N15/10 -> 6.2611887 | O23: =O15/10 -> 7.3134264 | P23: =P15/10 -> 8.3656641 | ... T23: =T15/10 -> 12.574615
H24: 2. Jahr | I24: =I16/10 -> 13.626853 | J24: =J16/10 -> 14.851411 | K24: =K16/10 -> 16.075969 | L24: =L16/10 -> 17.300527 | M24: =M16/10 -> 18.525085 | N24: =N16/10 -> 19.749643 | O24: =O16/10 -> 20.974202 | P24: =P16/10 -> 22.19876 | ... T24: =T16/10 -> 27.096992
H25: 3. Jahr | I25: =I17/10 -> 28.32155 | J25: =J17/10 -> 29.342457 | K25: =K17/10 -> 30.363364 | L25: =L17/10 -> 31.384271 | M25: =M17/10 -> 32.405177 | N25: =N17/10 -> 33.426084 | O25: =O17/10 -> 34.446991 | P25: =P17/10 -> 35.467898 | ... T25: =T17/10 -> 39.551525

Sheet Angebot und Nachfrage
A1: Anfertiger | B1: Valentin Maresch | C1: Bernhard Raab
B3: Jahr 1 | C3: Jahr 2 | D3: Jahr 3
A4: Erw. Nachfrage | B4: ='Nachfrage Jahr 1'!J32 -> 1803.9953 | C4: ='Nachfrage Jahr 2'!J32 -> 3688.2254 | D4: ='Nachfrage Jahr 3'!J32 -> 8158.0964
A5: Erw. Angebot | B5: =Angebotsentwicklung!U15 -> 814.4769 | C5: =Angebotsentwicklung!U16 -> 2443.4307 | D5: =Angebotsentwicklung!U17 -> 4072.3845

Sheet Umsatz Detail
A1: Anfertiger: | B1: Valentin Maresch | C1: Bernhard Raab
A3: Mieteinnahmen
A5: Stellplatz | B5: Host-Erlös/h (€ Range) | C5: SmartShift-Provision/h (€ Range) | D5: Endpreis Nutzer/h (€ Range) | E5: Stromkosten 1:1 (€/kWh) | F5: ØNutzungsrate/Tag (h) | G5: Host Einnahmen/Tag (€ Range) | H5: SmartShift Einnahmen/Tag (€ Range) | I5: Monatlicher Host-Umsatz (€) | J5: Monatlicher SmartShift-Umsatz (€) | K5: Risiko/Aufwand Host | L5: Mehrwert für Nutzer
A7: Außenstellplatz (80%) | B7: 1.5 | C7: =B7*0.15 -> 0.225 | D7: =B7+C7 -> 1.725 | E7: =Strompreis!E12 -> 0.29723333 | F7: 5 | G7: =B7*F7 -> 7.5 | H7: =C7*F7 -> 1.125 | I7: =G7*10 -> 75 | J7: =H7*10 -> 11.25 | K7: gering, da privates Grundstück | L7: einfache Anfahrt
A8: Garagenplatz (20%) | B8: 2 | C8: =B8*0.15 -> 0.3 | D8: =B8+C8 -> 2.3 | E8: =Strompreis!E12 -> 0.29723333 | F8: 5 | G8: =B8*F8 -> 10 | H8: =C8*F8 -> 1.5 | I8: =G8*10 -> 100 | J8: =H8*10 -> 15 | K8: mittel (Zugang, TG-Regeln) | L8: sicher, wettergeschützt
B12: Beispiel:
B13: Außenstellplatz | D13: Batteriekapazität KWh | E13: 20-80% KWh | F13: Standard Wallbox KWh | G13: 0-100 % in Stunden | H13: 20-80% Ladevergang in h | I13: Parkgebühr | J13: Stromkosten | K13: Provision | L13: Gesamt | N13: Vgl. Öffentl.
C14: 20-80% Ladung | D14: =Allgemein!C26 -> 73.625 | E14: =D14*0.6 -> 44.175 | F14: 11 | G14: =D14/F14 -> 6.6931818 | H14: =G14*0.6 -> 4.0159091 | I14: =H14*B7 -> 6.0238636 | J14: =E14*E7 -> 13.130283 | K14: =C7*H14 -> 0.90357955 | L14: =I14+J14+K14 -> 20.057726 | N14: =E14*0.49 -> 21.64575
B15: Garagenplatz | C15: 20-80% Ladung | D15: =D14 -> 73.625 | E15: =E14 -> 44.175 | F15: 11 | G15: =D15/F15 -> 6.6931818 | H15: =G15*0.6 -> 4.0159091 | I15: =H15*B8 -> 8.0318182 | J15: =E8*E15 -> 13.130283 | K15: =C8*H15 -> 1.2047727 | L15: =I15+J15+K15 -> 22.366873
A22: Werbeinnahmen: Themennahe Werbung auf unserer Website/App ab Jahr 2. Wir möchten, dass alle Werbeanzeigen mit dem Thema der Elektromobilität unmittelbar zu tuen hat
B25: Year 1 | N25: Year 2 | Z25: Year 3
B26: Jan | C26: Feb | D26: Mrz | E26: Apr | F26: Mai | G26: Jun | H26: Jul | I26: Aug | J26: Sep | K26: Okt | L26: Nov | M26: Dez | N26: Jan | O26: Feb | P26: Mrz | Q26: Apr | R26: Mai | S26: Jun | T26: Jul | U26: Aug | V26: Sep | W26: Okt | X26: Nov | Y26: Dez | Z26: Jan | AA26: Feb | AB26: Mrz | AC26: Apr | AD26: Mai | AE26: Jun | AF26: Jul | AG26: Aug | AH26: Sep | AI26: Okt | AJ26: Nov | AK26: Dez
A27: Anzahl Websiten Aufrufe | B27: 200 | C27: 300 | D27: 400 | E27: 500 | F27: 600 | G27: 700 | H27: 800 | I27: 900 | J27: 1000 | K27: 1100 | L27: 1200 | M27: 1300 | N27: 1500 | O27: 1700 | P27: 1900 | Q27: 2100 | R27: 2300 | S27: 2500 | T27: 2700 | U27: 2900 | V27: 3100 | W27: 3300 | X27: 3500 | Y27: 3700 | Z27: 4200 | AA27: 4700 | AB27: 5200 | AC27: 5700 | AD27: 6200 | AE27: 7200 | AF27: 7700 | AG27: 8200 | AH27: 8700 | AI27: 9200 | AJ27: 9700 | AK27: 10200
A28: Cost per click | B28: - | C28: - | D28: - | E28: - | F28: - | G28: - | H28: - | I28: - | J28: - | K28: - | L28: - | M28: - | N28: 0.3 | O28: 0.3 | P28: 0.3 | Q28: 0.3 | R28: 0.3 | S28: 0.3 | T28: 0.3 | U28: 0.3 | V28: 0.3 | W28: 0.3 | X28: 0.3 | Y28: 0.3 | Z28: 0.4 | AA28: 0.4 | AB28: 0.4 | AC28: 0.4 | AD28: 0.4 | AE28: 0.4 | AF28: 0.4 | AG28: 0.4 | AH28: 0.4 | AI28: 0.4 | AJ28: 0.4 | AK28: 0.4
A29: Revenue | B29: - | C29: - | D29: - | E29: - | F29: - | G29: - | H29: - | I29: - | J29: - | K29: - | L29: - | M29: - | N29: =N27*N28 -> 450 | O29: =O27*O28 -> 510 | P29: =P27*P28 -> 570 | Q29: =Q27*Q28 -> 630 | R29: =R27*R28 -> 690 | S29: =S27*S28 -> 750 | T29: =T27*T28 -> 810 | U29: =U27*U28 -> 870 | ... AK29: =AK27*AK28 -> 4080

Sheet GuV Tabelle
A1: Anfertiger: | B1: Valentin Maresch, Bernhard Raab; Hannes Hertel (Marketingaufwendungen)
C3: Year 1 | O3: Year 2 | AA3: Year 3
C4: Jan | D4: Feb | E4: Mrz | F4: Apr | G4: Mai | H4: Jun | I4: Jul | J4: Aug | K4: Sep | L4: Okt | M4: Nov | N4: Dez | O4: Jan | P4: Feb | Q4: Mrz | R4: Apr | S4: Mai | T4: Jun | U4: Jul | V4: Aug | W4: Sep | X4: Okt | Y4: Nov | Z4: Dez | AA4: Jan | AB4: Feb | AC4: Mrz | AD4: Apr | AE4: Mai | AF4: Jun | AG4: Jul | AH4: Aug | AI4: Sep | AJ4: Okt | AK4: Nov | AL4: Dez
B6: Umsatz pro Monat | C6: =(Angebotsentwicklung!I15*0.8*'Umsatz Detail'!$J$7)+(Angebotsentwicklung!I15*0.2*'Umsatz Detail'!$J$8) -> 120 | D6: =(Angebotsentwicklung!J15*0.8*'Umsatz Detail'!$J$7)+(Angebotsentwicklung!J15*0.2*'Umsatz Detail'!$J$8) -> 246.26853 | E6: =(Angebotsentwicklung!K15*0.8*'Umsatz Detail'!$J$7)+(Angebotsentwicklung!K15*0.2*'Umsatz Detail'!$J$8) -> 372.53706 | F6: =(Angebotsentwicklung!L15*0.8*'Umsatz Detail'!$J$7)+(Angebotsentwicklung!L15*0.2*'Umsatz Detail'!$J$8) -> 498.80558 | G6: =(Angebotsentwicklung!M15*0.8*'Umsatz Detail'!$J$7)+(Angebotsentwicklung!M15*0.2*'Umsatz Detail'!$J$8) -> 625.07411 | H6: =(Angebotsentwicklung!N15*0.8*'Umsatz Detail'!$J$7)+(Angebotsentwicklung!N15*0.2*'Umsatz Detail'!$J$8) -> 751.34264 | I6: =(Angebotsentwicklung!O15*0.8*'Umsatz Detail'!$J$7)+(Angebotsentwicklung!O15*0.2*'Umsatz Detail'!$J$8) -> 877.61117 | J6: =(Angebotsentwicklung!P15*0.8*'Umsatz Detail'!$J$7)+(Angebotsentwicklung!P15*0.2*'Umsatz Detail'!$J$8) -> 1003.8797 | ... N6: =(Angebotsentwicklung!T15*0.8*'Umsatz Detail'!$J$7)+(Angebotsentwicklung!T15*0.2*'Umsatz Detail'!$J$8) -> 1508.9538 | O6: =(Angebotsentwicklung!I16*0.8*'Umsatz Detail'!$J$7)+(Angebotsentwicklung!I16*0.2*'Umsatz Detail'!$J$8)+'Umsatz Detail'!N29 -> 2085.2223 | P6: =(Angebotsentwicklung!J16*0.8*'Umsatz Detail'!$J$7)+(Angebotsentwicklung!J16*0.2*'Umsatz Detail'!$J$8)+'Umsatz Detail'!O29 -> 2292.1693 | Q6: =(Angebotsentwicklung!K16*0.8*'Umsatz Detail'!$J$7)+(Angebotsentwicklung!K16*0.2*'Umsatz Detail'!$J$8)+'Umsatz Detail'!P29 -> 2499.1163 | R6: =(Angebotsentwicklung!L16*0.8*'Umsatz Detail'!$J$7)+(Angebotsentwicklung!L16*0.2*'Umsatz Detail'!$J$8)+'Umsatz Detail'!Q29 -> 2706.0633 | S6: =(Angebotsentwicklung!M16*0.8*'Umsatz Detail'!$J$7)+(Angebotsentwicklung!M16*0.2*'Umsatz Detail'!$J$8)+'Umsatz Detail'!R29 -> 2913.0102 | T6: =(Angebotsentwicklung!N16*0.8*'Umsatz Detail'!$J$7)+(Angebotsentwicklung!N16*0.2*'Umsatz Detail'!$J$8)+'Umsatz Detail'!S29 -> 3119.9572 | U6: =(Angebotsentwicklung!O16*0.8*'Umsatz Detail'!$J$7)+(Angebotsentwicklung!O16*0.2*'Umsatz Detail'!$J$8)+'Umsatz Detail'!T29 -> 3326.9042 | V6: =(Angebotsentwicklung!P16*0.8*'Umsatz Detail'!$J$7)+(Angebotsentwicklung!P16*0.2*'Umsatz Detail'!$J$8)+'Umsatz Detail'!U29 -> 3533.8512 | ... Z6: =(Angebotsentwicklung!T16*0.8*'Umsatz Detail'!$J$7)+(Angebotsentwicklung!T16*0.2*'Umsatz Detail'!$J$8)+'Umsatz Detail'!Y29 -> 4361.6391 | AA6: =(Angebotsentwicklung!I17*0.8*'Umsatz Detail'!$J$7)+(Angebotsentwicklung!I17*0.2*'Umsatz Detail'!$J$8)+'Umsatz Detail'!Z29 -> 5078.5861 | AB6: =(Angebotsentwicklung!J17*0.8*'Umsatz Detail'!$J$7)+(Angebotsentwicklung!J17*0.2*'Umsatz Detail'!$J$8)+'Umsatz Detail'!AA29 -> 5401.0949 | AC6: =(Angebotsentwicklung!K17*0.8*'Umsatz Detail'!$J$7)+(Angebotsentwicklung!K17*0.2*'Umsatz Detail'!$J$8)+'Umsatz Detail'!AB29 -> 5723.6037 | AD6: =(Angebotsentwicklung!L17*0.8*'Umsatz Detail'!$J$7)+(Angebotsentwicklung!L17*0.2*'Umsatz Detail'!$J$8)+'Umsatz Detail'!AC29 -> 6046.1125 | AE6: =(Angebotsentwicklung!M17*0.8*'Umsatz Detail'!$J$7)+(Angebotsentwicklung!M17*0.2*'Umsatz Detail'!$J$8)+'Umsatz Detail'!AD29 -> 6368.6213 | AF6: =(Angebotsentwicklung!N17*0.8*'Umsatz Detail'!$J$7)+(Angebotsentwicklung!N17*0.2*'Umsatz Detail'!$J$8)+'Umsatz Detail'!AE29 -> 6891.1301 | AG6: =(Angebotsentwicklung!O17*0.8*'Umsatz Detail'!$J$7)+(Angebotsentwicklung!O17*0.2*'Umsatz Detail'!$J$8)+'Umsatz Detail'!AF29 -> 7213.6389 | AH6: =(Angebotsentwicklung!P17*0.8*'Umsatz Detail'!$J$7)+(Angebotsentwicklung!P17*0.2*'Umsatz Detail'!$J$8)+'Umsatz Detail'!AG29 -> 7536.1477 | ... AL6: =(Angebotsentwicklung!T17*0.8*'Umsatz Detail'!$J$7)+(Angebotsentwicklung!T17*0.2*'Umsatz Detail'!$J$8)+'Umsatz Detail'!AK29 -> 8826.183
B8: Aufwendungen:
B10: Betriebshaftpflichtversicherung 15-30 € mntl. | C10: 20.42 | D10: 20.42 | E10: 20.42 | F10: 20.42 | G10: 20.42 | H10: 20.42 | I10: 20.42 | J10: 20.42 | K10: 20.42 | L10: 20.42 | M10: 20.42 | N10: 20.42 | O10: =20.42*1.05 -> 21.441 | P10: =20.42*1.05 -> 21.441 | Q10: =20.42*1.05 -> 21.441 | R10: =20.42*1.05 -> 21.441 | S10: =20.42*1.05 -> 21.441 | T10: =20.42*1.05 -> 21.441 | U10: =20.42*1.05 -> 21.441 | V10: =20.42*1.05 -> 21.441 | ... Z10: =20.42*1.05 -> 21.441 | AA10: =$Z$10*1.05 -> 22.51305 | AB10: =$Z$10*1.05 -> 22.51305 | AC10: =$Z$10*1.05 -> 22.51305 | AD10: =$Z$10*1.05 -> 22.51305 | AE10: =$Z$10*1.05 -> 22.51305 | AF10: =$Z$10*1.05 -> 22.51305 | AG10: =$Z$10*1.05 -> 22.51305 | AH10: =$Z$10*1.05 -> 22.51305 | ... AL10: =$Z$10*1.05 -> 22.51305
B11: Vermögensschadenhaftpflicht | C11: 30 | D11: 30 | E11: 30 | F11: 30 | G11: 30 | H11: 30 | I11: 30 | J11: 30 | K11: 30 | L11: 30 | M11: 30 | N11: 30 | O11: =30*1.05 -> 31.5 | P11: =30*1.05 -> 31.5 | Q11: =30*1.05 -> 31.5 | R11: =30*1.05 -> 31.5 | S11: =30*1.05 -> 31.5 | T11: =30*1.05 -> 31.5 | U11: =30*1.05 -> 31.5 | V11: =30*1.05 -> 31.5 | ... Z11: =30*1.05 -> 31.5 | AA11: =$Z$11*1.05 -> 33.075 | AB11: =$Z$11*1.05 -> 33.075 | AC11: =$Z$11*1.05 -> 33.075 | AD11: =$Z$11*1.05 -> 33.075 | AE11: =$Z$11*1.05 -> 33.075 | AF11: =$Z$11*1.05 -> 33.075 | AG11: =$Z$11*1.05 -> 33.075 | AH11: =$Z$11*1.05 -> 33.075 | ... AL11: =$Z$11*1.05 -> 33.075
B12: (Cyber Versicherung) | C12: 18.87 | D12: 18.87 | E12: 18.87 | F12: 18.87 | G12: 18.87 | H12: 18.87 | I12: 18.87 | J12: 18.87 | K12: 18.87 | L12: 18.87 | M12: 18.87 | N12: 18.87 | O12: =18.87*1.05 -> 19.8135 | P12: =18.87*1.05 -> 19.8135 | Q12: =18.87*1.05 -> 19.8135 | R12: =18.87*1.05 -> 19.8135 | S12: =18.87*1.05 -> 19.8135 | T12: =18.87*1.05 -> 19.8135 | U12: =18.87*1.05 -> 19.8135 | V12: =18.87*1.05 -> 19.8135 | ... Z12: =18.87*1.05 -> 19.8135 | AA12: =$Z$12*1.05 -> 20.804175 | AB12: =$Z$12*1.05 -> 20.804175 | AC12: =$Z$12*1.05 -> 20.804175 | AD12: =$Z$12*1.05 -> 20.804175 | AE12: =$Z$12*1.05 -> 20.804175 | AF12: =$Z$12*1.05 -> 20.804175 | AG12: =$Z$12*1.05 -> 20.804175 | AH12: =$Z$12*1.05 -> 20.804175 | ... AL12: =$Z$12*1.05 -> 20.804175
B13: Total Versicherungen | C13: =SUM(C10:C12) -> 69.29 | D13: =SUM(D10:D12) -> 69.29 | E13: =SUM(E10:E12) -> 69.29 | F13: =SUM(F10:F12) -> 69.29 | G13: =SUM(G10:G12) -> 69.29 | H13: =SUM(H10:H12) -> 69.29 | I13: =SUM(I10:I12) -> 69.29 | J13: =SUM(J10:J12) -> 69.29 | ... AL13: =SUM(AL10:AL12) -> 76.392225
B15: IHK Beitrag | C15: 0 | D15: 0 | E15: 0 | F15: 0 | G15: 0 | H15: 0 | I15: 0 | J15: 0 | K15: 0 | L15: 0 | M15: 0 | N15: 0 | O15: 0 | P15: 0 | Q15: 0 | R15: 0 | S15: 0 | T15: 0 | U15: 0 | V15: 0 | W15: 0 | X15: 0 | Y15: 0 | Z15: 0 | AA15: 0 | AB15: 0 | AC15: 0 | AD15: 0 | AE15: 0 | AF15: 0 | AG15: 0 | AH15: 0 | AI15: 0 | AJ15: 0 | AK15: 0 | AL15: 0
B16: Domain + E-Mail Postfach | C16: =(3*2)/12 -> 0.5 | D16: =(3*2)/12 -> 0.5 | E16: =(3*2)/12 -> 0.5 | F16: =(3*2)/12 -> 0.5 | G16: =(3*2)/12 -> 0.5 | H16: =(3*2)/12 -> 0.5 | I16: =(3*2)/12 -> 0.5 | J16: =(3*2)/12 -> 0.5 | ... N16: =(3*2)/12 -> 0.5 | O16: =(19*2)/12 -> 3.1666667 | P16: =(19*2)/12 -> 3.1666667 | Q16: =(19*2)/12 -> 3.1666667 | R16: =(19*2)/12 -> 3.1666667 | S16: =(19*2)/12 -> 3.1666667 | T16: =(19*2)/12 -> 3.1666667 | U16: =(19*2)/12 -> 3.1666667 | V16: =(19*2)/12 -> 3.1666667 | ... AL16: =(19*2)/12 -> 3.1666667
B17: Server
B18: Anmeldung Kleingewerbe (einmalig) | C18: 60
B19: Softwarekosten (MS Office) | C19: =5*5.6 -> 28 | D19: =5*5.6 -> 28 | E19: =5*5.6 -> 28 | F19: =5*5.6 -> 28 | G19: =5*5.6 -> 28 | H19: =5*5.6 -> 28 | I19: =5*5.6 -> 28 | J19: =5*5.6 -> 28 | ... AL19: =5*5.6 -> 28
B20: Payment Anbieter (0,15€/Ladung) | C20: =Angebotsentwicklung!I15*0.15 -> 1.5 | D20: =Angebotsentwicklung!J15*0.15 -> 3.0783566 | E20: =Angebotsentwicklung!K15*0.15 -> 4.6567132 | F20: =Angebotsentwicklung!L15*0.15 -> 6.2350698 | G20: =Angebotsentwicklung!M15*0.15 -> 7.8134264 | H20: =Angebotsentwicklung!N15*0.15 -> 9.391783 | I20: =Angebotsentwicklung!O15*0.15 -> 10.97014 | J20: =Angebotsentwicklung!P15*0.15 -> 12.548496 | ... N20: =Angebotsentwicklung!T15*0.15 -> 18.861923 | O20: =Angebotsentwicklung!I16*0.15 -> 20.440279 | P20: =Angebotsentwicklung!J16*0.15 -> 22.277116 | Q20: =Angebotsentwicklung!K16*0.15 -> 24.113954 | R20: =Angebotsentwicklung!L16*0.15 -> 25.950791 | S20: =Angebotsentwicklung!M16*0.15 -> 27.787628 | T20: =Angebotsentwicklung!N16*0.15 -> 29.624465 | U20: =Angebotsentwicklung!O16*0.15 -> 31.461302 | V20: =Angebotsentwicklung!P16*0.15 -> 33.29814 | ... Z20: =Angebotsentwicklung!T16*0.15 -> 40.645489 | AA20: =Angebotsentwicklung!I17*0.15 -> 42.482326 | AB20: =Angebotsentwicklung!J17*0.15 -> 44.013686 | AC20: =Angebotsentwicklung!K17*0.15 -> 45.545046 | AD20: =Angebotsentwicklung!L17*0.15 -> 47.076406 | AE20: =Angebotsentwicklung!M17*0.15 -> 48.607766 | AF20: =Angebotsentwicklung!N17*0.15 -> 50.139126 | AG20: =Angebotsentwicklung!O17*0.15 -> 51.670486 | AH20: =Angebotsentwicklung!P17*0.15 -> 53.201847 | ... AL20: =Angebotsentwicklung!T17*0.15 -> 59.327287
B21: Hosting/Storage | C21: 50 | D21: 50 | E21: 50 | F21: 50 | G21: 50 | H21: 50 | I21: 50 | J21: 50 | K21: 50 | L21: 50 | M21: 50 | N21: 50 | O21: 100 | P21: 100 | Q21: 100 | R21: 100 | S21: 100 | T21: 100 | U21: 100 | V21: 100 | W21: 100 | X21: 100 | Y21: 100 | Z21: 100 | AA21: 200 | AB21: 200 | AC21: 200 | AD21: 200 | AE21: 200 | AF21: 200 | AG21: 200 | AH21: 200 | AI21: 200 | AJ21: 200 | AK21: 200 | AL21: 200
B22: Total Beiträge | C22: =SUM(C15:C21) -> 140 | D22: =SUM(D15:D21) -> 81.578357 | E22: =SUM(E15:E21) -> 83.156713 | F22: =SUM(F15:F21) -> 84.73507 | G22: =SUM(G15:G21) -> 86.313426 | H22: =SUM(H15:H21) -> 87.891783 | I22: =SUM(I15:I21) -> 89.47014 | J22: =SUM(J15:J21) -> 91.048496 | ... AL22: =SUM(AL15:AL21) -> 290.49395
B24: Gehalt Vollzeit Brutto 2 Personen | C24: =1500*2 -> 3000 | D24: =1500*2 -> 3000 | E24: =1500*2 -> 3000 | F24: =1500*2 -> 3000 | G24: =1500*2 -> 3000 | H24: =1500*2 -> 3000 | I24: =1500*2 -> 3000 | J24: =1500*2 -> 3000 | ... N24: =1500*2 -> 3000 | O24: =1650*2 -> 3300 | P24: =1650*2 -> 3300 | Q24: =1650*2 -> 3300 | R24: =1650*2 -> 3300 | S24: =1650*2 -> 3300 | T24: =1650*2 -> 3300 | U24: =1650*2 -> 3300 | V24: =1650*2 -> 3300 | ... Z24: =1650*2 -> 3300 | AA24: =1800*2 -> 3600 | AB24: =1800*2 -> 3600 | AC24: =1800*2 -> 3600 | AD24: =1800*2 -> 3600 | AE24: =1800*2 -> 3600 | AF24: =1800*2 -> 3600 | AG24: =1800*2 -> 3600 | AH24: =1800*2 -> 3600 | ... AL24: =1800*2 -> 3600
B25: Gehalt Teilzeit 1 Person | C25: =1500/2 -> 750 | D25: =1500/2 -> 750 | E25: =1500/2 -> 750 | F25: =1500/2 -> 750 | G25: =1500/2 -> 750 | H25: =1500/2 -> 750 | I25: =1500/2 -> 750 | J25: =1500/2 -> 750 | ... N25: =1500/2 -> 750 | O25: =1650/2 -> 825 | P25: =1650/2 -> 825 | Q25: =1650/2 -> 825 | R25: =1650/2 -> 825 | S25: =1650/2 -> 825 | T25: =1650/2 -> 825 | U25: =1650/2 -> 825 | V25: =1650/2 -> 825 | ... Z25: =1650/2 -> 825 | AA25: =1800/2 -> 900 | AB25: =1800/2 -> 900 | AC25: =1800/2 -> 900 | AD25: =1800/2 -> 900 | AE25: =1800/2 -> 900 | AF25: =1800/2 -> 900 | AG25: =1800/2 -> 900 | AH25: =1800/2 -> 900 | ... AL25: =1800/2 -> 900 | XFD25: =1500/2 -> 750
B26: Total Gehalt | C26: =C24+C25 -> 3750 | D26: =D24+D25 -> 3750 | E26: =E24+E25 -> 3750 | F26: =F24+F25 -> 3750 | G26: =G24+G25 -> 3750 | H26: =H24+H25 -> 3750 | I26: =I24+I25 -> 3750 | J26: =J24+J25 -> 3750 | ... N26: =N24+N25 -> 3750 | O26: =SUM(O24:O25) -> 4125 | P26: =SUM(P24:P25) -> 4125 | Q26: =SUM(Q24:Q25) -> 4125 | R26: =SUM(R24:R25) -> 4125 | S26: =SUM(S24:S25) -> 4125 | T26: =SUM(T24:T25) -> 4125 | U26: =SUM(U24:U25) -> 4125 | V26: =SUM(V24:V25) -> 4125 | ... AL26: =SUM(AL24:AL25) -> 4500
B28: Marketingaufwendungen | C28: =SUM(Marketingplan!B37:B41) -> 3350 | D28: =SUM(Marketingplan!C37:C41) -> 1850 | E28: =SUM(Marketingplan!D37:D41) -> 1100 | F28: =SUM(Marketingplan!E37:E41) -> 1100 | G28: =SUM(Marketingplan!F37:F41) -> 1100 | H28: =SUM(Marketingplan!G37:G41) -> 1100 | I28: =SUM(Marketingplan!H37:H41) -> 1100 | J28: =SUM(Marketingplan!I37:I41) -> 1100 | ... N28: =SUM(Marketingplan!M37:M41) -> 600 | O28: =SUM(Marketingplan!B51:B55) -> 1550 | P28: =SUM(Marketingplan!C51:C55) -> 1050 | Q28: =SUM(Marketingplan!D51:D55) -> 800 | R28: =SUM(Marketingplan!E51:E55) -> 1300 | S28: =SUM(Marketingplan!F51:F55) -> 1800 | T28: =SUM(Marketingplan!G51:G55) -> 800 | U28: =SUM(Marketingplan!H51:H55) -> 800 | V28: =SUM(Marketingplan!I51:I55) -> 800 | ... Z28: =SUM(Marketingplan!M51:M55) -> 300 | AA28: =SUM(Marketingplan!B65:B69) -> 1900 | AB28: =SUM(Marketingplan!C65:C69) -> 1400 | AC28: =SUM(Marketingplan!D65:D69) -> 1400 | AD28: =SUM(Marketingplan!E65:E69) -> 1800 | AE28: =SUM(Marketingplan!F65:F69) -> 1650 | AF28: =SUM(Marketingplan!G65:G69) -> 2050 | AG28: =SUM(Marketingplan!H65:H69) -> 900 | AH28: =SUM(Marketingplan!I65:I69) -> 1400 | ... AL28: =SUM(Marketingplan!M65:M69) -> 900
B31: Total Aufwendungen | C31: =SUM(C13+C22+C28+C26) -> 7309.29 | D31: =SUM(D13+D22+D28+D26) -> 5750.8684 | E31: =SUM(E13+E22+E28+E26) -> 5002.4467 | F31: =SUM(F13+F22+F28+F26) -> 5004.0251 | G31: =SUM(G13+G22+G28+G26) -> 5005.6034 | H31: =SUM(H13+H22+H28+H26) -> 5007.1818 | I31: =SUM(I13+I22+I28+I26) -> 5008.7601 | J31: =SUM(J13+J22+J28+J26) -> 5010.3385 | ... AL31: =SUM(AL13+AL22+AL28+AL26) -> 5766.8862
B33: Monatliches Ergebnis | C33: =C6-C31 -> -7189.29 | D33: =D6-D31 -> -5504.5998 | E33: =E6-E31 -> -4629.9097 | F33: =F6-F31 -> -4505.2195 | G33: =G6-G31 -> -4380.5293 | H33: =H6-H31 -> -4255.8391 | I33: =I6-I31 -> -4131.149 | J33: =J6-J31 -> -4006.4588 | ... AL33: =AL6-AL31 -> 3059.2968
E37: Umsatz | G37: Kosten | H37: Gewinn vor Steuern | I37: Steuern (25%) | J37: Gewinn n. Steuern
B38: Idee:
B39: 1. Jahr | C39: Kleingewerbe | E39: =SUM(C6:N6) -> 9773.7228 | G39: =-SUM(C31:N31) -> -61655.652 | H39: =SUM(C33:N33) -> -51881.929 | I39: 0 | J39: =H39-I39 -> -51881.929
B40: 2. Jahr | C40: Kleingewerbe | E40: =SUM(O6:Z6) -> 38681.168 | G40: =-SUM(O31:Z31) -> -62913.569 | H40: =SUM(O33:Z33) -> -24232.4 | I40: 0 | J40: =H40-I40 -> -24232.4
B41: 3. Jahr | C41: Regelbesteuerung | E41: =SUM(AA6:AL6) -> 83628.614 | G41: =-SUM(AA31:AL31) -> -74901.564 | H41: =SUM(AA33:AL33) -> 8727.0498 | I41: =-(H41*0.25) -> -2181.7624 | J41: =(H41-(-I41)) -> 6545.2873
H42: =SUM(H39:H41) -> -67387.279 | I42: =SUM(I39:I41) -> -2181.7624 | J42: =SUM(J39:J41) -> -69569.042

Sheet Break Even Analysis
A1: Anfertiger: | B1: Valentin Maresch | C1: Bernhard Raab
B5: 2026 | N5: 2027 | Z5: 2028
B6: 1 | C6: 2 | D6: 3 | E6: 4 | F6: 5 | G6: 6 | H6: 7 | I6: 8 | J6: 9 | K6: 10 | L6: 11 | M6: 12 | N6: 1 | O6: 2 | P6: 3 | Q6: 4 | R6: 5 | S6: 6 | T6: 7 | U6: 8 | V6: 9 | W6: 10 | X6: 11 | Y6: 12 | Z6: 1 | AA6: 2 | AB6: 3 | AC6: 4 | AD6: 5 | AE6: 6 | AF6: 7 | AG6: 8 | AH6: 9 | AI6: 10 | AJ6: 11 | AK6: 12
A7: Turn over | B7: ='GuV Tabelle'!C6 -> 120 | C7: ='GuV Tabelle'!D6 -> 246.26853 | D7: ='GuV Tabelle'!E6 -> 372.53706 | E7: ='GuV Tabelle'!F6 -> 498.80558 | F7: ='GuV Tabelle'!G6 -> 625.07411 | G7: ='GuV Tabelle'!H6 -> 751.34264 | H7: ='GuV Tabelle'!I6 -> 877.61117 | I7: ='GuV Tabelle'!J6 -> 1003.8797 | ... AK7: ='GuV Tabelle'!AL6 -> 8826.183
A8: Cost | B8: ='GuV Tabelle'!C31 -> 7309.29 | C8: ='GuV Tabelle'!D31 -> 5750.8684 | D8: ='GuV Tabelle'!E31 -> 5002.4467 | E8: ='GuV Tabelle'!F31 -> 5004.0251 | F8: ='GuV Tabelle'!G31 -> 5005.6034 | G8: ='GuV Tabelle'!H31 -> 5007.1818 | H8: ='GuV Tabelle'!I31 -> 5008.7601 | I8: ='GuV Tabelle'!J31 -> 5010.3385 | ... AK8: ='GuV Tabelle'!AL31 -> 5766.8862
A9: Profit/Loss | B9: =B7-B8 -> -7189.29 | C9: =C7-C8 -> -5504.5998 | D9: =D7-D8 -> -4629.9097 | E9: =E7-E8 -> -4505.2195 | F9: =F7-F8 -> -4380.5293 | G9: =G7-G8 -> -4255.8391 | H9: =H7-H8 -> -4131.149 | I9: =I7-I8 -> -4006.4588 | ... AK9: =AK7-AK8 -> 3059.2968

Sheet Marketingplan
A1: Anfertiger: Hannes Hertel
A3: Marketingplan für SmartShift
A7: Ziele und Annahmen
A9: Hauptregion: Münchner Osten (Riem, Trudering, Berg am Laim)
A11: Fokus-ZG: Anwohner in den Fokusregionen
A12: in Apartments wohnend, Alter: 28-55, Interesse an E-Autos
A16: Maßnahmen und Budgetaufteilung (Jahr 1)
A18: Maßnahme | B18: Ziel | E18: Jahresbudget | H18: Kommentar
A20: Messe Aufsteller | B20: Sichtbarkeit, Networking, Neukunden Aquise | E20: 3000-5000€ | H20: Standkosten, Material, Flyer | L20: IAA Mobility Messe Sep.26 / Autotage München
A21: Flyer/Koop. mit lokalen Autohäusern | B21: Zugang zu E-Auto Interessenten in Zielregion | E21: 1000-1500€ | H21: östliches München, Wasserburger Landstraße | L21: Bsp: Autohaus Hemmerle, Automag GmBH | O21: Autohaus Eder München-Trudering, Tesla Service Center
A22: SEA: Google + Meta Ads | B22: Online Reichweite, App Downloads, Anfragen | E22: 6000-7000€ | H22: an ZG orientieren
A23: Social Media TT und IG | B23: Organische Reichweite, Markenaufbau, Giveaways | E23: 0 | H23: nur Zeitaufwand nötig
A24: Lokale PR/ Zeitung etc. | B24: Vertrauen gewinnen, Reichweite in Zielregion | E24: 500-1000€
A25: Reserve und Tests | B25: Optimierungen und Lernkurven | E25: 1000
A32: Jahr 1 | B32: Jan | C32: Feb | D32: Mrz | E32: Apr | F32: Mai | G32: Jun | H32: Jul | I32: Aug | J32: Sep | K32: Okt | L32: Nov | M32: Dez | N32: Gesamt
A34: Umsatz pro Monat | B34: 292.5 | C34: 479.97 | D34: 667.43 | E34: 854.9 | F34: 1042.36 | G34: 1229.83 | H34: 1417.3 | I34: 1604.76 | J34: 1792.23 | K34: 1979.69 | L34: 2167.16 | M34: 2354.63 | N34: =SUM(B34:M34) -> 15882.76
A36: Marketingkosten
A37: Messe | B37: 750 | C37: 750 | D37: 500 | E37: 500 | F37: 500 | G37: 500 | H37: 500 | I37: 500 | J37: 500 | N37: =SUM(B37:M37) -> 5000
A38: Flyer | B38: 1500 | N38: =SUM(B38:M38) -> 1500
A39: Google/Meta ADS | B39: 500 | C39: 500 | D39: 500 | E39: 500 | F39: 500 | G39: 500 | H39: 500 | I39: 500 | J39: 500 | K39: 500 | L39: 500 | M39: 500 | N39: =SUM(B39:M39) -> 6000 | P39: CPC in Muc 1,5-3,5€
A40: PR/Zeitung | B40: 500 | C40: 500 | N40: =SUM(B40:C40) -> 1000
A41: Reserve Tests | B41: 100 | C41: 100 | D41: 100 | E41: 100 | F41: 100 | G41: 100 | H41: 100 | I41: 100 | J41: 100 | K41: 100 | L41: 100 | M41: 100 | N41: =SUM(B41:M41) -> 1200
A42: Gesamt Kosten Marketing | N42: =SUM(N37:N41) -> 14700
A46: Jahr 2 | B46: Jan | C46: Feb | D46: Mrz | E46: Apr | F46: Mai | G46: Jun | H46: Jul | I46: Aug | J46: Sep | K46: Okt | L46: Nov | M46: Dez | N46: Gesamt
A48: Umsatz pro Monat | B48: ='GuV Tabelle'!O6 -> 2085.2223 | C48: ='GuV Tabelle'!P6 -> 2292.1693 | D48: ='GuV Tabelle'!Q6 -> 2499.1163 | E48: ='GuV Tabelle'!R6 -> 2706.0633 | F48: ='GuV Tabelle'!S6 -> 2913.0102 | G48: ='GuV Tabelle'!T6 -> 3119.9572 | H48: ='GuV Tabelle'!U6 -> 3326.9042 | I48: ='GuV Tabelle'!V6 -> 3533.8512 | ... M48: ='GuV Tabelle'!Z6 -> 4361.6391 | N48: =SUM(B48:M48) -> 38681.168
A50: Marketingkosten
A51: Messe | B51: 750 | C51: 750 | D51: 500 | E51: 500 | F51: 500 | G51: 500 | H51: 500 | I51: 500 | J51: 500 | N51: =SUM(B51:M51) -> 5000
A52: Flyer | B52: 500 | F52: 500 | N52: =SUM(B52:M52) -> 1000
A53: Google/Meta ADS | B53: 200 | C53: 200 | D53: 200 | E53: 200 | F53: 200 | G53: 200 | H53: 200 | I53: 200 | J53: 200 | K53: 200 | L53: 200 | M53: 200 | N53: =SUM(B53:M53) -> 2400 | P53: zielgerichtete lokale Nutzer
A54: PR/Zeitung | E54: 500 | F54: 500 | N54: =SUM(B54:M54) -> 1000 | P54: Münchner Osten, Zeitpunkt: nach Winter vor Messe
A55: Reserve Tests | B55: 100 | C55: 100 | D55: 100 | E55: 100 | F55: 100 | G55: 100 | H55: 100 | I55: 100 | J55: 100 | K55: 100 | L55: 100 | M55: 100 | N55: =SUM(B55:M55) -> 1200
A56: Gesamt Kosten Marketing | N56: =SUM(N51:N55) -> 10600
A60: Jahr 3 | B60: Jan | C60: Feb | D60: Mrz | E60: Apr | F60: Mai | G60: Jun | H60: Jul | I60: Aug | J60: Sep | K60: Okt | L60: Nov | M60: Dez | N60: Gesamt
A62: Umsatz pro Monat | B62: ='GuV Tabelle'!AA6 -> 5078.5861 | C62: ='GuV Tabelle'!AB6 -> 5401.0949 | D62: ='GuV Tabelle'!AC6 -> 5723.6037 | E62: ='GuV Tabelle'!AD6 -> 6046.1125 | F62: ='GuV Tabelle'!AE6 -> 6368.6213 | G62: ='GuV Tabelle'!AF6 -> 6891.1301 | H62: ='GuV Tabelle'!AG6 -> 7213.6389 | I62: ='GuV Tabelle'!AH6 -> 7536.1477 | ... M62: ='GuV Tabelle'!AL6 -> 8826.183 | N62: =SUM(B62:M62) -> 83628.614
A64: Marketingkosten
A65: Messe | B65: 1000 | C65: 1000 | D65: 1000 | E65: 1000 | F65: 500 | G65: 500 | H65: 500 | I65: 1000 | J65: 1000 | N65: =SUM(B65:M65) -> 7500 | P65: Standgröße anpassen, andere Events wie Power2Drive
A66: Flyer | F66: 750 | G66: 750 | N66: =SUM(B66:M66) -> 1500
A67: Google/Meta ADS | B67: 300 | C67: 300 | D67: 300 | E67: 300 | F67: 300 | G67: 300 | H67: 300 | I67: 300 | J67: 300 | K67: 300 | L67: 300 | M67: 300 | N67: =SUM(B67:M67) -> 3600
A68: PR/Zeitung | B68: 500 | E68: 400 | F68: 0 | G68: 400 | J68: 1000 | M68: 500 | N68: =SUM(B68:M68) -> 2800 | P68: lokale Medien, Messe.PR, große Anzeige SZ während Europäischer Mobilitätswoche, Jahresabschluss
A69: Reserve Tests | B69: 100 | C69: 100 | D69: 100 | E69: 100 | F69: 100 | G69: 100 | H69: 100 | I69: 100 | J69: 100 | K69: 100 | L69: 100 | M69: 100 | N69: =SUM(B69:M69) -> 1200
...
